Workbook

Sheet Transactions
A1: Date | B1: Category | C1: Description | D1: Income (₹) | E1: Expense (₹) | F1: Balance (₹)
A2: 01-Apr-2024 | B2: Salary | C2: Monthly Salary | D2: 45000 | F2: =IF(ROW()=2,D2-E2,F1+D2-E2) -> 45000
A3: 01-Apr-2024 | B3: Rent | C3: House Rent | E3: 12000 | F3: =IF(ROW()=2,D2-E2,F2+D3-E3) -> 33000 | L3: Groceries | M3: =SUMIF(B:B, "Groceries",E:E ) -> 8200 | N3: =SUMIF(Transactions!B:B,"Salary",D:D) + SUMIF(B:B,"Freelance",D:D) -> 65000
A4: 02-Apr-2024 | B4: Groceries | C4: Big Bazaar Shopping | E4: 2800 | F4: =IF(ROW()=2,D2-E2,F3+D4-E4) -> 30200 | L4: Salary | M4: =SUMIF(B:B, "Salary",D:D ) -> 48000 | N4: =SUM(Transactions!E:E) -> 46114
A5: 03-Apr-2024 | B5: Transport | C5: Monthly Bus Pass | E5: 900 | F5: =IF(ROW()=2,D2-E2,F4+D5-E5) -> 29300 | L5: Rent | M5: =SUMIF(B:B, "Rent",E:E ) -> 13500 | N5: =N3-N4 -> 18886
A6: 04-Apr-2024 | B6: Food | C6: Restaurant – friends | E6: 650 | F6: =IF(ROW()=2,D2-E2,F5+D6-E6) -> 28650 | N6: =(N5/N3)*100 -> 29.055385
A7: 05-Apr-2024 | B7: Utilities | C7: Electricity Bill | E7: 1200 | F7: =IF(ROW()=2,D2-E2,F6+D7-E7) -> 27450
A8: 06-Apr-2024 | B8: Mobile | C8: Mobile Recharge | E8: 499 | F8: =IF(ROW()=2,D2-E2,F7+D8-E8) -> 26951
A9: 07-Apr-2024 | B9: Groceries | C9: Daily Vegetables | E9: 430 | F9: =IF(ROW()=2,D2-E2,F8+D9-E9) -> 26521
A10: 08-Apr-2024 | B10: Entertainment | C10: Netflix Subscription | E10: 499 | F10: =IF(ROW()=2,D2-E2,F9+D10-E10) -> 26022
A11: 09-Apr-2024 | B11: Transport | C11: Ola Cab | E11: 280 | F11: =IF(ROW()=2,D2-E2,F10+D11-E11) -> 25742
A12: 10-Apr-2024 | B12: Food | C12: Zomato Order | E12: 380 | F12: =IF(ROW()=2,D2-E2,F11+D12-E12) -> 25362
A13: 11-Apr-2024 | B13: Freelance | C13: Freelance Payment | D13: 8000 | F13: =IF(ROW()=2,D2-E2,F12+D13-E13) -> 33362
A14: 12-Apr-2024 | B14: Groceries | C14: Supermarket | E14: 1100 | F14: =IF(ROW()=2,D2-E2,F13+D14-E14) -> 32262
A15: 13-Apr-2024 | B15: Clothing | C15: New Shirt | E15: 999 | F15: =IF(ROW()=2,D2-E2,F14+D15-E15) -> 31263
A16: 14-Apr-2024 | B16: Healthcare | C16: Doctor Visit | E16: 500 | F16: =IF(ROW()=2,D2-E2,F15+D16-E16) -> 30763
A17: 15-Apr-2024 | B17: Utilities | C17: Internet Bill | E17: 799 | F17: =IF(ROW()=2,D2-E2,F16+D17-E17) -> 29964
A18: 16-Apr-2024 | B18: Food | C18: Coffee Shop | E18: 220 | F18: =IF(ROW()=2,D2-E2,F17+D18-E18) -> 29744
A19: 17-Apr-2024 | B19: Transport | C19: Petrol | E19: 1500 | F19: =IF(ROW()=2,D2-E2,F18+D19-E19) -> 28244
A20: 18-Apr-2024 | B20: Education | C20: Online Course | E20: 1499 | F20: =IF(ROW()=2,D2-E2,F19+D20-E20) -> 26745
A21: 19-Apr-2024 | B21: Groceries | C21: Weekly Grocery | E21: 1850 | F21: =IF(ROW()=2,D2-E2,F20+D21-E21) -> 24895
A22: 20-Apr-2024 | B22: Entertainment | C22: Movie Ticket | E22: 350 | F22: =IF(ROW()=2,D2-E2,F21+D22-E22) -> 24545
A23: 21-Apr-2024 | B23: Savings | C23: RD Deposit | E23: 5000 | F23: =IF(ROW()=2,D2-E2,F22+D23-E23) -> 19545
A24: 22-Apr-2024 | B24: Food | C24: Lunch at Office | E24: 180 | F24: =IF(ROW()=2,D2-E2,F23+D24-E24) -> 19365
A25: 23-Apr-2024 | B25: Freelance | C25: Design Project | D25: 5000 | F25: =IF(ROW()=2,D2-E2,F24+D25-E25) -> 24365
A26: 24-Apr-2024 | B26: Clothing | C26: Shoes | E26: 1800 | F26: =IF(ROW()=2,D2-E2,F25+D26-E26) -> 22565
A27: 25-Apr-2024 | B27: Transport | C27: Metro Card Recharge | E27: 500 | F27: =IF(ROW()=2,D2-E2,F26+D27-E27) -> 22065
A28: 26-Apr-2024 | B28: Groceries | C28: Fruits & Snacks | E28: 620 | F28: =IF(ROW()=2,D2-E2,F27+D28-E28) -> 21445
A29: 27-Apr-2024 | B29: Utilities | C29: Gas Cylinder | E29: 950 | F29: =IF(ROW()=2,D2-E2,F28+D29-E29) -> 20495
A30: 28-Apr-2024 | B30: Food | C30: Home Delivery | E30: 450 | F30: =IF(ROW()=2,D2-E2,F29+D30-E30) -> 20045
A31: 29-Apr-2024 | B31: Healthcare | C31: Medicines | E31: 340 | F31: =IF(ROW()=2,D2-E2,F30+D31-E31) -> 19705
A32: 30-Apr-2024 | B32: Salary | C32: Bonus Payment | D32: 3000 | F32: =IF(ROW()=2,D2-E2,F31+D32-E32) -> 22705
A33: 30-Apr-2024 | B33: Entertainment | C33: Amazon Prime | E33: 299 | F33: =IF(ROW()=2,D2-E2,F32+D33-E33) -> 22406
A34: 30-Apr-2024 | B34: Miscellaneous | C34: Stationery | E34: 200 | F34: =IF(ROW()=2,D2-E2,F33+D34-E34) -> 22206
A35: 30-Apr-2024 | B35: Savings | C35: FD Top-up | E35: 3000 | F35: =IF(ROW()=2,D2-E2,F34+D35-E35) -> 19206
A36: 30-Apr-2024 | B36: Groceries | C36: Month-end stock | E36: 1400 | F36: =IF(ROW()=2,D2-E2,F35+D36-E36) -> 17806
A37: 30-Apr-2024 | B37: Transport | C37: Auto Rickshaw | E37: 120 | F37: =IF(ROW()=2,D2-E2,F36+D37-E37) -> 17686
A38: 30-Apr-2024 | B38: Food | C38: Birthday Treat | E38: 800 | F38: =IF(ROW()=2,D2-E2,F37+D38-E38) -> 16886
A39: 30-Apr-2024 | B39: Rent | C39: Maintenance Charges | E39: 1500 | F39: =IF(ROW()=2,D2-E2,F38+D39-E39) -> 15386
A40: 30-Apr-2024 | B40: Miscellaneous | C40: Gift for friend | E40: 500 | F40: =IF(ROW()=2,D2-E2,F39+D40-E40) -> 14886
...

Sheet Sheet1
A3: Row Labels | B3: Count of Expense (₹)
A4: Clothing | B4: 2
A5: Education | B5: 1
A6: Entertainment | B6: 3
A7: Food | B7: 6
A8: Freelance
A9: Groceries | B9: 6
A10: Healthcare | B10: 2
A11: Miscellaneous | B11: 2
A12: Mobile | B12: 1
A13: Rent | B13: 2
A14: Salary
A15: Savings | B15: 2
A16: Transport | B16: 5
A17: Utilities | B17: 3
A18: Grand Total | B18: 35

Sheet Summary
A1: Category-wise Expense Breakdown | E1: Income Sources
A2: Category | B2: Total Expense (₹) | C2: % of Total | E2: Source | F2: Total Income (₹)
A3: Rent | B3: =SUMIF(Transactions!B:B,"Rent",Transactions!E:E) -> 13500 | C3: =IF(B3=0,"",B3/SUM($B$3:$B$14)*100) -> 29.275274 | E3: Salary | F3: =SUMIF(Transactions!B:B,"Salary",Transactions!D:D) -> 48000
A4: Groceries | B4: =SUMIF(Transactions!B:B,"Groceries",Transactions!E:E) -> 8200 | C4: =IF(B4=0,"",B4/SUM($B$3:$B$14)*100) -> 17.782018 | E4: Freelance | F4: =SUMIF(Transactions!B:B,"Freelance",Transactions!D:D) -> 17000
A5: Food | B5: =SUMIF(Transactions!B:B,"Food",Transactions!E:E) -> 2680 | C5: =IF(B5=0,"",B5/SUM($B$3:$B$14)*100) -> 5.8116841 | E5: TOTAL INCOME | F5: =SUM(F3:F4) -> 65000
A6: Transport | B6: =SUMIF(Transactions!B:B,"Transport",Transactions!E:E) -> 3300 | C6: =IF(B6=0,"",B6/SUM($B$3:$B$14)*100) -> 7.1561782
A7: Utilities | B7: =SUMIF(Transactions!B:B,"Utilities",Transactions!E:E) -> 2949 | C7: =IF(B7=0,"",B7/SUM($B$3:$B$14)*100) -> 6.395021
A8: Entertainment | B8: =SUMIF(Transactions!B:B,"Entertainment",Transactions!E:E) -> 1148 | C8: =IF(B8=0,"",B8/SUM($B$3:$B$14)*100) -> 2.4894826
A9: Clothing | B9: =SUMIF(Transactions!B:B,"Clothing",Transactions!E:E) -> 2799 | C9: =IF(B9=0,"",B9/SUM($B$3:$B$14)*100) -> 6.0697402
A10: Healthcare | B10: =SUMIF(Transactions!B:B,"Healthcare",Transactions!E:E) -> 840 | C10: =IF(B10=0,"",B10/SUM($B$3:$B$14)*100) -> 1.8215726
A11: Education | B11: =SUMIF(Transactions!B:B,"Education",Transactions!E:E) -> 1499 | C11: =IF(B11=0,"",B11/SUM($B$3:$B$14)*100) -> 3.2506397
A12: Savings | B12: =SUMIF(Transactions!B:B,"Savings",Transactions!E:E) -> 8000 | C12: =IF(B12=0,"",B12/SUM($B$3:$B$14)*100) -> 17.348311
A13: Mobile | B13: =SUMIF(Transactions!B:B,"Mobile",Transactions!E:E) -> 499 | C13: =IF(B13=0,"",B13/SUM($B$3:$B$14)*100) -> 1.0821009
A14: Miscellaneous | B14: =SUMIF(Transactions!B:B,"Miscellaneous",Transactions!E:E) -> 700 | C14: =IF(B14=0,"",B14/SUM($B$3:$B$14)*100) -> 1.5179772
A15: TOTAL | B15: =SUM(B3:B14) -> 46114 | C15: 100%

Sheet Dashboard
A1: 💰 Personal Finance Dashboard – April 2024
A4: Total Income | C4: Total Expense | E4: Net Savings | G4: Savings Rate
A5: =SUMIF(Transactions!B:B,"Salary",Transactions!D:D)+SUMIF(Transactions!B:B,"Freelance",Transactions!D:D) -> 65000 | C5: =SUM(Transactions!E:E) -> 46114 | E5: =A5-C5 -> 18886 | G5: =IF(A5=0,"N/A",TEXT((E5/A5)*100,"0.0")&"%") -> 29.1%
A8: Top Expense Categories
A9: Category | B9: Expense (₹) | C9: % Share | D9: Bar
A10: Rent | B10: =SUMIF(Transactions!B:B,"Rent",Transactions!E:E) -> 13500 | C10: =IF(B10=0,"",TEXT(B10/SUM($B$10:$B$14)*100,"0.0")&"%") -> 37.8% | D10: =REPT("█",ROUND(B10/SUM($B$10:$B$14)*20,0)) -> ████████
A11: Savings | B11: =SUMIF(Transactions!B:B,"Savings",Transactions!E:E) -> 8000 | C11: =IF(B11=0,"",TEXT(B11/SUM($B$10:$B$14)*100,"0.0")&"%") -> 22.4% | D11: =REPT("█",ROUND(B11/SUM($B$10:$B$14)*20,0)) -> ████
A12: Groceries | B12: =SUMIF(Transactions!B:B,"Groceries",Transactions!E:E) -> 8200 | C12: =IF(B12=0,"",TEXT(B12/SUM($B$10:$B$14)*100,"0.0")&"%") -> 23.0% | D12: =REPT("█",ROUND(B12/SUM($B$10:$B$14)*20,0)) -> █████
A13: Transport | B13: =SUMIF(Transactions!B:B,"Transport",Transactions!E:E) -> 3300 | C13: =IF(B13=0,"",TEXT(B13/SUM($B$10:$B$14)*100,"0.0")&"%") -> 9.2% | D13: =REPT("█",ROUND(B13/SUM($B$10:$B$14)*20,0)) -> ██
A14: Food | B14: =SUMIF(Transactions!B:B,"Food",Transactions!E:E) -> 2680 | C14: =IF(B14=0,"",TEXT(B14/SUM($B$10:$B$14)*100,"0.0")&"%") -> 7.5% | D14: =REPT("█",ROUND(B14/SUM($B$10:$B$14)*20,0)) -> ██
A16: 📌 Tip: Edit data in the 'Transactions' sheet — all figures update automatically!
